[TerminalIPythonApp] ERROR | Failed to create history session in /draco/u/aenge/.ipython/profile_default/history.sqlite. History will not be saved.
Traceback (most recent call last):
  File "/mpcdf/soft/SLE_12/packages/x86_64/anaconda/3/2020.02/lib/python3.7/site-packages/IPython/core/history.py", line 543, in __init__
    self.new_session()
  File "</mpcdf/soft/SLE_12/packages/x86_64/anaconda/3/2020.02/lib/python3.7/site-packages/decorator.py:decorator-gen-22>", line 2, in new_session
  File "/mpcdf/soft/SLE_12/packages/x86_64/anaconda/3/2020.02/lib/python3.7/site-packages/IPython/core/history.py", line 58, in needs_sqlite
    return f(self, *a, **kw)
  File "/mpcdf/soft/SLE_12/packages/x86_64/anaconda/3/2020.02/lib/python3.7/site-packages/IPython/core/history.py", line 569, in new_session
    NULL, "") """, (datetime.datetime.now(),))
sqlite3.OperationalError: database is locked
[TerminalIPythonApp] ERROR | Failed to create history session in /draco/u/aenge/.ipython/profile_default/history.sqlite. History will not be saved.
Traceback (most recent call last):
  File "/mpcdf/soft/SLE_12/packages/x86_64/anaconda/3/2020.02/lib/python3.7/site-packages/IPython/core/history.py", line 543, in __init__
    self.new_session()
  File "</mpcdf/soft/SLE_12/packages/x86_64/anaconda/3/2020.02/lib/python3.7/site-packages/decorator.py:decorator-gen-22>", line 2, in new_session
  File "/mpcdf/soft/SLE_12/packages/x86_64/anaconda/3/2020.02/lib/python3.7/site-packages/IPython/core/history.py", line 58, in needs_sqlite
    return f(self, *a, **kw)
  File "/mpcdf/soft/SLE_12/packages/x86_64/anaconda/3/2020.02/lib/python3.7/site-packages/IPython/core/history.py", line 569, in new_session
    NULL, "") """, (datetime.datetime.now(),))
sqlite3.OperationalError: database is locked
[TerminalIPythonApp] ERROR | Failed to create history session in /draco/u/aenge/.ipython/profile_default/history.sqlite. History will not be saved.
Traceback (most recent call last):
  File "/mpcdf/soft/SLE_12/packages/x86_64/anaconda/3/2020.02/lib/python3.7/site-packages/IPython/core/history.py", line 543, in __init__
    self.new_session()
  File "</mpcdf/soft/SLE_12/packages/x86_64/anaconda/3/2020.02/lib/python3.7/site-packages/decorator.py:decorator-gen-22>", line 2, in new_session
  File "/mpcdf/soft/SLE_12/packages/x86_64/anaconda/3/2020.02/lib/python3.7/site-packages/IPython/core/history.py", line 58, in needs_sqlite
    return f(self, *a, **kw)
  File "/mpcdf/soft/SLE_12/packages/x86_64/anaconda/3/2020.02/lib/python3.7/site-packages/IPython/core/history.py", line 569, in new_session
    NULL, "") """, (datetime.datetime.now(),))
sqlite3.OperationalError: database is locked
[TerminalIPythonApp] ERROR | Failed to create history session in /draco/u/aenge/.ipython/profile_default/history.sqlite. History will not be saved.
Traceback (most recent call last):
  File "/mpcdf/soft/SLE_12/packages/x86_64/anaconda/3/2020.02/lib/python3.7/site-packages/IPython/core/history.py", line 543, in __init__
    self.new_session()
  File "</mpcdf/soft/SLE_12/packages/x86_64/anaconda/3/2020.02/lib/python3.7/site-packages/decorator.py:decorator-gen-22>", line 2, in new_session
  File "/mpcdf/soft/SLE_12/packages/x86_64/anaconda/3/2020.02/lib/python3.7/site-packages/IPython/core/history.py", line 58, in needs_sqlite
    return f(self, *a, **kw)
  File "/mpcdf/soft/SLE_12/packages/x86_64/anaconda/3/2020.02/lib/python3.7/site-packages/IPython/core/history.py", line 569, in new_session
    NULL, "") """, (datetime.datetime.now(),))
sqlite3.OperationalError: database is locked
[TerminalIPythonApp] ERROR | Failed to create history session in /draco/u/aenge/.ipython/profile_default/history.sqlite. History will not be saved.
Traceback (most recent call last):
  File "/mpcdf/soft/SLE_12/packages/x86_64/anaconda/3/2020.02/lib/python3.7/site-packages/IPython/core/history.py", line 543, in __init__
    self.new_session()
  File "</mpcdf/soft/SLE_12/packages/x86_64/anaconda/3/2020.02/lib/python3.7/site-packages/decorator.py:decorator-gen-22>", line 2, in new_session
  File "/mpcdf/soft/SLE_12/packages/x86_64/anaconda/3/2020.02/lib/python3.7/site-packages/IPython/core/history.py", line 58, in needs_sqlite
    return f(self, *a, **kw)
  File "/mpcdf/soft/SLE_12/packages/x86_64/anaconda/3/2020.02/lib/python3.7/site-packages/IPython/core/history.py", line 569, in new_session
    NULL, "") """, (datetime.datetime.now(),))
sqlite3.OperationalError: database is locked
[TerminalIPythonApp] ERROR | Failed to create history session in /draco/u/aenge/.ipython/profile_default/history.sqlite. History will not be saved.
Traceback (most recent call last):
  File "/mpcdf/soft/SLE_12/packages/x86_64/anaconda/3/2020.02/lib/python3.7/site-packages/IPython/core/history.py", line 543, in __init__
    self.new_session()
  File "</mpcdf/soft/SLE_12/packages/x86_64/anaconda/3/2020.02/lib/python3.7/site-packages/decorator.py:decorator-gen-22>", line 2, in new_session
  File "/mpcdf/soft/SLE_12/packages/x86_64/anaconda/3/2020.02/lib/python3.7/site-packages/IPython/core/history.py", line 58, in needs_sqlite
    return f(self, *a, **kw)
  File "/mpcdf/soft/SLE_12/packages/x86_64/anaconda/3/2020.02/lib/python3.7/site-packages/IPython/core/history.py", line 569, in new_session
    NULL, "") """, (datetime.datetime.now(),))
sqlite3.OperationalError: database is locked
[TerminalIPythonApp] ERROR | Failed to create history session in /draco/u/aenge/.ipython/profile_default/history.sqlite. History will not be saved.
Traceback (most recent call last):
  File "/mpcdf/soft/SLE_12/packages/x86_64/anaconda/3/2020.02/lib/python3.7/site-packages/IPython/core/history.py", line 543, in __init__
    self.new_session()
  File "</mpcdf/soft/SLE_12/packages/x86_64/anaconda/3/2020.02/lib/python3.7/site-packages/decorator.py:decorator-gen-22>", line 2, in new_session
  File "/mpcdf/soft/SLE_12/packages/x86_64/anaconda/3/2020.02/lib/python3.7/site-packages/IPython/core/history.py", line 58, in needs_sqlite
    return f(self, *a, **kw)
  File "/mpcdf/soft/SLE_12/packages/x86_64/anaconda/3/2020.02/lib/python3.7/site-packages/IPython/core/history.py", line 569, in new_session
    NULL, "") """, (datetime.datetime.now(),))
sqlite3.OperationalError: database is locked
[TerminalIPythonApp] ERROR | Failed to create history session in /draco/u/aenge/.ipython/profile_default/history.sqlite. History will not be saved.
Traceback (most recent call last):
  File "/mpcdf/soft/SLE_12/packages/x86_64/anaconda/3/2020.02/lib/python3.7/site-packages/IPython/core/history.py", line 543, in __init__
    self.new_session()
  File "</mpcdf/soft/SLE_12/packages/x86_64/anaconda/3/2020.02/lib/python3.7/site-packages/decorator.py:decorator-gen-22>", line 2, in new_session
  File "/mpcdf/soft/SLE_12/packages/x86_64/anaconda/3/2020.02/lib/python3.7/site-packages/IPython/core/history.py", line 58, in needs_sqlite
    return f(self, *a, **kw)
  File "/mpcdf/soft/SLE_12/packages/x86_64/anaconda/3/2020.02/lib/python3.7/site-packages/IPython/core/history.py", line 569, in new_session
    NULL, "") """, (datetime.datetime.now(),))
sqlite3.OperationalError: database is locked
[TerminalIPythonApp] ERROR | Failed to create history session in /draco/u/aenge/.ipython/profile_default/history.sqlite. History will not be saved.
Traceback (most recent call last):
  File "/mpcdf/soft/SLE_12/packages/x86_64/anaconda/3/2020.02/lib/python3.7/site-packages/IPython/core/history.py", line 543, in __init__
    self.new_session()
  File "</mpcdf/soft/SLE_12/packages/x86_64/anaconda/3/2020.02/lib/python3.7/site-packages/decorator.py:decorator-gen-22>", line 2, in new_session
  File "/mpcdf/soft/SLE_12/packages/x86_64/anaconda/3/2020.02/lib/python3.7/site-packages/IPython/core/history.py", line 58, in needs_sqlite
    return f(self, *a, **kw)
  File "/mpcdf/soft/SLE_12/packages/x86_64/anaconda/3/2020.02/lib/python3.7/site-packages/IPython/core/history.py", line 569, in new_session
    NULL, "") """, (datetime.datetime.now(),))
sqlite3.OperationalError: database is locked
[TerminalIPythonApp] ERROR | Failed to create history session in /draco/u/aenge/.ipython/profile_default/history.sqlite. History will not be saved.
Traceback (most recent call last):
  File "/mpcdf/soft/SLE_12/packages/x86_64/anaconda/3/2020.02/lib/python3.7/site-packages/IPython/core/history.py", line 543, in __init__
    self.new_session()
  File "</mpcdf/soft/SLE_12/packages/x86_64/anaconda/3/2020.02/lib/python3.7/site-packages/decorator.py:decorator-gen-22>", line 2, in new_session
  File "/mpcdf/soft/SLE_12/packages/x86_64/anaconda/3/2020.02/lib/python3.7/site-packages/IPython/core/history.py", line 58, in needs_sqlite
    return f(self, *a, **kw)
  File "/mpcdf/soft/SLE_12/packages/x86_64/anaconda/3/2020.02/lib/python3.7/site-packages/IPython/core/history.py", line 569, in new_session
    NULL, "") """, (datetime.datetime.now(),))
sqlite3.OperationalError: database is locked
[TerminalIPythonApp] ERROR | Failed to create history session in /draco/u/aenge/.ipython/profile_default/history.sqlite. History will not be saved.
Traceback (most recent call last):
  File "/mpcdf/soft/SLE_12/packages/x86_64/anaconda/3/2020.02/lib/python3.7/site-packages/IPython/core/history.py", line 543, in __init__
    self.new_session()
  File "</mpcdf/soft/SLE_12/packages/x86_64/anaconda/3/2020.02/lib/python3.7/site-packages/decorator.py:decorator-gen-22>", line 2, in new_session
  File "/mpcdf/soft/SLE_12/packages/x86_64/anaconda/3/2020.02/lib/python3.7/site-packages/IPython/core/history.py", line 58, in needs_sqlite
    return f(self, *a, **kw)
  File "/mpcdf/soft/SLE_12/packages/x86_64/anaconda/3/2020.02/lib/python3.7/site-packages/IPython/core/history.py", line 569, in new_session
    NULL, "") """, (datetime.datetime.now(),))
sqlite3.OperationalError: database is locked
[TerminalIPythonApp] ERROR | Failed to create history session in /draco/u/aenge/.ipython/profile_default/history.sqlite. History will not be saved.
Traceback (most recent call last):
  File "/mpcdf/soft/SLE_12/packages/x86_64/anaconda/3/2020.02/lib/python3.7/site-packages/IPython/core/history.py", line 543, in __init__
    self.new_session()
  File "</mpcdf/soft/SLE_12/packages/x86_64/anaconda/3/2020.02/lib/python3.7/site-packages/decorator.py:decorator-gen-22>", line 2, in new_session
  File "/mpcdf/soft/SLE_12/packages/x86_64/anaconda/3/2020.02/lib/python3.7/site-packages/IPython/core/history.py", line 58, in needs_sqlite
    return f(self, *a, **kw)
  File "/mpcdf/soft/SLE_12/packages/x86_64/anaconda/3/2020.02/lib/python3.7/site-packages/IPython/core/history.py", line 569, in new_session
    NULL, "") """, (datetime.datetime.now(),))
sqlite3.OperationalError: database is locked
[TerminalIPythonApp] ERROR | Failed to create history session in /draco/u/aenge/.ipython/profile_default/history.sqlite. History will not be saved.
Traceback (most recent call last):
  File "/mpcdf/soft/SLE_12/packages/x86_64/anaconda/3/2020.02/lib/python3.7/site-packages/IPython/core/history.py", line 543, in __init__
    self.new_session()
  File "</mpcdf/soft/SLE_12/packages/x86_64/anaconda/3/2020.02/lib/python3.7/site-packages/decorator.py:decorator-gen-22>", line 2, in new_session
  File "/mpcdf/soft/SLE_12/packages/x86_64/anaconda/3/2020.02/lib/python3.7/site-packages/IPython/core/history.py", line 58, in needs_sqlite
    return f(self, *a, **kw)
  File "/mpcdf/soft/SLE_12/packages/x86_64/anaconda/3/2020.02/lib/python3.7/site-packages/IPython/core/history.py", line 569, in new_session
    NULL, "") """, (datetime.datetime.now(),))
sqlite3.OperationalError: database is locked
[TerminalIPythonApp] ERROR | Failed to create history session in /draco/u/aenge/.ipython/profile_default/history.sqlite. History will not be saved.
Traceback (most recent call last):
  File "/mpcdf/soft/SLE_12/packages/x86_64/anaconda/3/2020.02/lib/python3.7/site-packages/IPython/core/history.py", line 543, in __init__
    self.new_session()
  File "</mpcdf/soft/SLE_12/packages/x86_64/anaconda/3/2020.02/lib/python3.7/site-packages/decorator.py:decorator-gen-22>", line 2, in new_session
  File "/mpcdf/soft/SLE_12/packages/x86_64/anaconda/3/2020.02/lib/python3.7/site-packages/IPython/core/history.py", line 58, in needs_sqlite
    return f(self, *a, **kw)
  File "/mpcdf/soft/SLE_12/packages/x86_64/anaconda/3/2020.02/lib/python3.7/site-packages/IPython/core/history.py", line 569, in new_session
    NULL, "") """, (datetime.datetime.now(),))
sqlite3.OperationalError: database is locked
[TerminalIPythonApp] ERROR | Failed to create history session in /draco/u/aenge/.ipython/profile_default/history.sqlite. History will not be saved.
Traceback (most recent call last):
  File "/mpcdf/soft/SLE_12/packages/x86_64/anaconda/3/2020.02/lib/python3.7/site-packages/IPython/core/history.py", line 543, in __init__
    self.new_session()
  File "</mpcdf/soft/SLE_12/packages/x86_64/anaconda/3/2020.02/lib/python3.7/site-packages/decorator.py:decorator-gen-22>", line 2, in new_session
  File "/mpcdf/soft/SLE_12/packages/x86_64/anaconda/3/2020.02/lib/python3.7/site-packages/IPython/core/history.py", line 58, in needs_sqlite
    return f(self, *a, **kw)
  File "/mpcdf/soft/SLE_12/packages/x86_64/anaconda/3/2020.02/lib/python3.7/site-packages/IPython/core/history.py", line 569, in new_session
    NULL, "") """, (datetime.datetime.now(),))
sqlite3.OperationalError: database is locked
[TerminalIPythonApp] ERROR | Failed to create history session in /draco/u/aenge/.ipython/profile_default/history.sqlite. History will not be saved.
Traceback (most recent call last):
  File "/mpcdf/soft/SLE_12/packages/x86_64/anaconda/3/2020.02/lib/python3.7/site-packages/IPython/core/history.py", line 543, in __init__
    self.new_session()
  File "</mpcdf/soft/SLE_12/packages/x86_64/anaconda/3/2020.02/lib/python3.7/site-packages/decorator.py:decorator-gen-22>", line 2, in new_session
  File "/mpcdf/soft/SLE_12/packages/x86_64/anaconda/3/2020.02/lib/python3.7/site-packages/IPython/core/history.py", line 58, in needs_sqlite
    return f(self, *a, **kw)
  File "/mpcdf/soft/SLE_12/packages/x86_64/anaconda/3/2020.02/lib/python3.7/site-packages/IPython/core/history.py", line 569, in new_session
    NULL, "") """, (datetime.datetime.now(),))
sqlite3.OperationalError: database is locked
[TerminalIPythonApp] ERROR | Failed to create history session in /draco/u/aenge/.ipython/profile_default/history.sqlite. History will not be saved.
Traceback (most recent call last):
  File "/mpcdf/soft/SLE_12/packages/x86_64/anaconda/3/2020.02/lib/python3.7/site-packages/IPython/core/history.py", line 543, in __init__
    self.new_session()
  File "</mpcdf/soft/SLE_12/packages/x86_64/anaconda/3/2020.02/lib/python3.7/site-packages/decorator.py:decorator-gen-22>", line 2, in new_session
  File "/mpcdf/soft/SLE_12/packages/x86_64/anaconda/3/2020.02/lib/python3.7/site-packages/IPython/core/history.py", line 58, in needs_sqlite
    return f(self, *a, **kw)
  File "/mpcdf/soft/SLE_12/packages/x86_64/anaconda/3/2020.02/lib/python3.7/site-packages/IPython/core/history.py", line 569, in new_session
    NULL, "") """, (datetime.datetime.now(),))
sqlite3.OperationalError: database is locked
[TerminalIPythonApp] ERROR | Failed to create history session in /draco/u/aenge/.ipython/profile_default/history.sqlite. History will not be saved.
Traceback (most recent call last):
  File "/mpcdf/soft/SLE_12/packages/x86_64/anaconda/3/2020.02/lib/python3.7/site-packages/IPython/core/history.py", line 543, in __init__
    self.new_session()
  File "</mpcdf/soft/SLE_12/packages/x86_64/anaconda/3/2020.02/lib/python3.7/site-packages/decorator.py:decorator-gen-22>", line 2, in new_session
  File "/mpcdf/soft/SLE_12/packages/x86_64/anaconda/3/2020.02/lib/python3.7/site-packages/IPython/core/history.py", line 58, in needs_sqlite
    return f(self, *a, **kw)
  File "/mpcdf/soft/SLE_12/packages/x86_64/anaconda/3/2020.02/lib/python3.7/site-packages/IPython/core/history.py", line 569, in new_session
    NULL, "") """, (datetime.datetime.now(),))
sqlite3.OperationalError: database is locked
[TerminalIPythonApp] ERROR | Failed to create history session in /draco/u/aenge/.ipython/profile_default/history.sqlite. History will not be saved.
Traceback (most recent call last):
  File "/mpcdf/soft/SLE_12/packages/x86_64/anaconda/3/2020.02/lib/python3.7/site-packages/IPython/core/history.py", line 543, in __init__
    self.new_session()
  File "</mpcdf/soft/SLE_12/packages/x86_64/anaconda/3/2020.02/lib/python3.7/site-packages/decorator.py:decorator-gen-22>", line 2, in new_session
  File "/mpcdf/soft/SLE_12/packages/x86_64/anaconda/3/2020.02/lib/python3.7/site-packages/IPython/core/history.py", line 58, in needs_sqlite
    return f(self, *a, **kw)
  File "/mpcdf/soft/SLE_12/packages/x86_64/anaconda/3/2020.02/lib/python3.7/site-packages/IPython/core/history.py", line 569, in new_session
    NULL, "") """, (datetime.datetime.now(),))
sqlite3.OperationalError: database is locked
[TerminalIPythonApp] ERROR | Failed to create history session in /draco/u/aenge/.ipython/profile_default/history.sqlite. History will not be saved.
Traceback (most recent call last):
  File "/mpcdf/soft/SLE_12/packages/x86_64/anaconda/3/2020.02/lib/python3.7/site-packages/IPython/core/history.py", line 543, in __init__
    self.new_session()
  File "</mpcdf/soft/SLE_12/packages/x86_64/anaconda/3/2020.02/lib/python3.7/site-packages/decorator.py:decorator-gen-22>", line 2, in new_session
  File "/mpcdf/soft/SLE_12/packages/x86_64/anaconda/3/2020.02/lib/python3.7/site-packages/IPython/core/history.py", line 58, in needs_sqlite
    return f(self, *a, **kw)
  File "/mpcdf/soft/SLE_12/packages/x86_64/anaconda/3/2020.02/lib/python3.7/site-packages/IPython/core/history.py", line 569, in new_session
    NULL, "") """, (datetime.datetime.now(),))
sqlite3.OperationalError: database is locked
[TerminalIPythonApp] ERROR | Failed to create history session in /draco/u/aenge/.ipython/profile_default/history.sqlite. History will not be saved.
Traceback (most recent call last):
  File "/mpcdf/soft/SLE_12/packages/x86_64/anaconda/3/2020.02/lib/python3.7/site-packages/IPython/core/history.py", line 543, in __init__
    self.new_session()
  File "</mpcdf/soft/SLE_12/packages/x86_64/anaconda/3/2020.02/lib/python3.7/site-packages/decorator.py:decorator-gen-22>", line 2, in new_session
  File "/mpcdf/soft/SLE_12/packages/x86_64/anaconda/3/2020.02/lib/python3.7/site-packages/IPython/core/history.py", line 58, in needs_sqlite
    return f(self, *a, **kw)
  File "/mpcdf/soft/SLE_12/packages/x86_64/anaconda/3/2020.02/lib/python3.7/site-packages/IPython/core/history.py", line 569, in new_session
    NULL, "") """, (datetime.datetime.now(),))
sqlite3.OperationalError: database is locked
[TerminalIPythonApp] ERROR | Failed to create history session in /draco/u/aenge/.ipython/profile_default/history.sqlite. History will not be saved.
Traceback (most recent call last):
  File "/mpcdf/soft/SLE_12/packages/x86_64/anaconda/3/2020.02/lib/python3.7/site-packages/IPython/core/history.py", line 543, in __init__
    self.new_session()
  File "</mpcdf/soft/SLE_12/packages/x86_64/anaconda/3/2020.02/lib/python3.7/site-packages/decorator.py:decorator-gen-22>", line 2, in new_session
  File "/mpcdf/soft/SLE_12/packages/x86_64/anaconda/3/2020.02/lib/python3.7/site-packages/IPython/core/history.py", line 58, in needs_sqlite
    return f(self, *a, **kw)
  File "/mpcdf/soft/SLE_12/packages/x86_64/anaconda/3/2020.02/lib/python3.7/site-packages/IPython/core/history.py", line 569, in new_session
    NULL, "") """, (datetime.datetime.now(),))
sqlite3.OperationalError: database is locked
[TerminalIPythonApp] ERROR | Failed to create history session in /draco/u/aenge/.ipython/profile_default/history.sqlite. History will not be saved.
Traceback (most recent call last):
  File "/mpcdf/soft/SLE_12/packages/x86_64/anaconda/3/2020.02/lib/python3.7/site-packages/IPython/core/history.py", line 543, in __init__
    self.new_session()
  File "</mpcdf/soft/SLE_12/packages/x86_64/anaconda/3/2020.02/lib/python3.7/site-packages/decorator.py:decorator-gen-22>", line 2, in new_session
  File "/mpcdf/soft/SLE_12/packages/x86_64/anaconda/3/2020.02/lib/python3.7/site-packages/IPython/core/history.py", line 58, in needs_sqlite
    return f(self, *a, **kw)
  File "/mpcdf/soft/SLE_12/packages/x86_64/anaconda/3/2020.02/lib/python3.7/site-packages/IPython/core/history.py", line 569, in new_session
    NULL, "") """, (datetime.datetime.now(),))
sqlite3.OperationalError: database is locked
[TerminalIPythonApp] ERROR | Failed to create history session in /draco/u/aenge/.ipython/profile_default/history.sqlite. History will not be saved.
Traceback (most recent call last):
  File "/mpcdf/soft/SLE_12/packages/x86_64/anaconda/3/2020.02/lib/python3.7/site-packages/IPython/core/history.py", line 543, in __init__
    self.new_session()
  File "</mpcdf/soft/SLE_12/packages/x86_64/anaconda/3/2020.02/lib/python3.7/site-packages/decorator.py:decorator-gen-22>", line 2, in new_session
  File "/mpcdf/soft/SLE_12/packages/x86_64/anaconda/3/2020.02/lib/python3.7/site-packages/IPython/core/history.py", line 58, in needs_sqlite
    return f(self, *a, **kw)
  File "/mpcdf/soft/SLE_12/packages/x86_64/anaconda/3/2020.02/lib/python3.7/site-packages/IPython/core/history.py", line 569, in new_session
    NULL, "") """, (datetime.datetime.now(),))
sqlite3.OperationalError: database is locked
[TerminalIPythonApp] ERROR | Failed to create history session in /draco/u/aenge/.ipython/profile_default/history.sqlite. History will not be saved.
Traceback (most recent call last):
  File "/mpcdf/soft/SLE_12/packages/x86_64/anaconda/3/2020.02/lib/python3.7/site-packages/IPython/core/history.py", line 543, in __init__
    self.new_session()
  File "</mpcdf/soft/SLE_12/packages/x86_64/anaconda/3/2020.02/lib/python3.7/site-packages/decorator.py:decorator-gen-22>", line 2, in new_session
  File "/mpcdf/soft/SLE_12/packages/x86_64/anaconda/3/2020.02/lib/python3.7/site-packages/IPython/core/history.py", line 58, in needs_sqlite
    return f(self, *a, **kw)
  File "/mpcdf/soft/SLE_12/packages/x86_64/anaconda/3/2020.02/lib/python3.7/site-packages/IPython/core/history.py", line 569, in new_session
    NULL, "") """, (datetime.datetime.now(),))
sqlite3.OperationalError: database is locked
[TerminalIPythonApp] ERROR | Failed to create history session in /draco/u/aenge/.ipython/profile_default/history.sqlite. History will not be saved.
Traceback (most recent call last):
  File "/mpcdf/soft/SLE_12/packages/x86_64/anaconda/3/2020.02/lib/python3.7/site-packages/IPython/core/history.py", line 543, in __init__
    self.new_session()
  File "</mpcdf/soft/SLE_12/packages/x86_64/anaconda/3/2020.02/lib/python3.7/site-packages/decorator.py:decorator-gen-22>", line 2, in new_session
  File "/mpcdf/soft/SLE_12/packages/x86_64/anaconda/3/2020.02/lib/python3.7/site-packages/IPython/core/history.py", line 58, in needs_sqlite
    return f(self, *a, **kw)
  File "/mpcdf/soft/SLE_12/packages/x86_64/anaconda/3/2020.02/lib/python3.7/site-packages/IPython/core/history.py", line 569, in new_session
    NULL, "") """, (datetime.datetime.now(),))
sqlite3.OperationalError: database is locked
[TerminalIPythonApp] ERROR | Failed to create history session in /draco/u/aenge/.ipython/profile_default/history.sqlite. History will not be saved.
Traceback (most recent call last):
  File "/mpcdf/soft/SLE_12/packages/x86_64/anaconda/3/2020.02/lib/python3.7/site-packages/IPython/core/history.py", line 543, in __init__
    self.new_session()
  File "</mpcdf/soft/SLE_12/packages/x86_64/anaconda/3/2020.02/lib/python3.7/site-packages/decorator.py:decorator-gen-22>", line 2, in new_session
  File "/mpcdf/soft/SLE_12/packages/x86_64/anaconda/3/2020.02/lib/python3.7/site-packages/IPython/core/history.py", line 58, in needs_sqlite
    return f(self, *a, **kw)
  File "/mpcdf/soft/SLE_12/packages/x86_64/anaconda/3/2020.02/lib/python3.7/site-packages/IPython/core/history.py", line 569, in new_session
    NULL, "") """, (datetime.datetime.now(),))
sqlite3.OperationalError: database is locked
[TerminalIPythonApp] ERROR | Failed to create history session in /draco/u/aenge/.ipython/profile_default/history.sqlite. History will not be saved.
Traceback (most recent call last):
  File "/mpcdf/soft/SLE_12/packages/x86_64/anaconda/3/2020.02/lib/python3.7/site-packages/IPython/core/history.py", line 543, in __init__
    self.new_session()
  File "</mpcdf/soft/SLE_12/packages/x86_64/anaconda/3/2020.02/lib/python3.7/site-packages/decorator.py:decorator-gen-22>", line 2, in new_session
  File "/mpcdf/soft/SLE_12/packages/x86_64/anaconda/3/2020.02/lib/python3.7/site-packages/IPython/core/history.py", line 58, in needs_sqlite
    return f(self, *a, **kw)
  File "/mpcdf/soft/SLE_12/packages/x86_64/anaconda/3/2020.02/lib/python3.7/site-packages/IPython/core/history.py", line 569, in new_session
    NULL, "") """, (datetime.datetime.now(),))
sqlite3.OperationalError: database is locked
[TerminalIPythonApp] ERROR | Failed to create history session in /draco/u/aenge/.ipython/profile_default/history.sqlite. History will not be saved.
Traceback (most recent call last):
  File "/mpcdf/soft/SLE_12/packages/x86_64/anaconda/3/2020.02/lib/python3.7/site-packages/IPython/core/history.py", line 543, in __init__
    self.new_session()
  File "</mpcdf/soft/SLE_12/packages/x86_64/anaconda/3/2020.02/lib/python3.7/site-packages/decorator.py:decorator-gen-22>", line 2, in new_session
  File "/mpcdf/soft/SLE_12/packages/x86_64/anaconda/3/2020.02/lib/python3.7/site-packages/IPython/core/history.py", line 58, in needs_sqlite
    return f(self, *a, **kw)
  File "/mpcdf/soft/SLE_12/packages/x86_64/anaconda/3/2020.02/lib/python3.7/site-packages/IPython/core/history.py", line 569, in new_session
    NULL, "") """, (datetime.datetime.now(),))
sqlite3.OperationalError: database is locked
[TerminalIPythonApp] ERROR | Failed to create history session in /draco/u/aenge/.ipython/profile_default/history.sqlite. History will not be saved.
Traceback (most recent call last):
  File "/mpcdf/soft/SLE_12/packages/x86_64/anaconda/3/2020.02/lib/python3.7/site-packages/IPython/core/history.py", line 543, in __init__
    self.new_session()
  File "</mpcdf/soft/SLE_12/packages/x86_64/anaconda/3/2020.02/lib/python3.7/site-packages/decorator.py:decorator-gen-22>", line 2, in new_session
  File "/mpcdf/soft/SLE_12/packages/x86_64/anaconda/3/2020.02/lib/python3.7/site-packages/IPython/core/history.py", line 58, in needs_sqlite
    return f(self, *a, **kw)
  File "/mpcdf/soft/SLE_12/packages/x86_64/anaconda/3/2020.02/lib/python3.7/site-packages/IPython/core/history.py", line 569, in new_session
    NULL, "") """, (datetime.datetime.now(),))
sqlite3.OperationalError: database is locked
[TerminalIPythonApp] ERROR | Failed to create history session in /draco/u/aenge/.ipython/profile_default/history.sqlite. History will not be saved.
Traceback (most recent call last):
  File "/mpcdf/soft/SLE_12/packages/x86_64/anaconda/3/2020.02/lib/python3.7/site-packages/IPython/core/history.py", line 543, in __init__
    self.new_session()
  File "</mpcdf/soft/SLE_12/packages/x86_64/anaconda/3/2020.02/lib/python3.7/site-packages/decorator.py:decorator-gen-22>", line 2, in new_session
  File "/mpcdf/soft/SLE_12/packages/x86_64/anaconda/3/2020.02/lib/python3.7/site-packages/IPython/core/history.py", line 58, in needs_sqlite
    return f(self, *a, **kw)
  File "/mpcdf/soft/SLE_12/packages/x86_64/anaconda/3/2020.02/lib/python3.7/site-packages/IPython/core/history.py", line 569, in new_session
    NULL, "") """, (datetime.datetime.now(),))
sqlite3.OperationalError: database is locked
[TerminalIPythonApp] ERROR | Failed to create history session in /draco/u/aenge/.ipython/profile_default/history.sqlite. History will not be saved.
Traceback (most recent call last):
  File "/mpcdf/soft/SLE_12/packages/x86_64/anaconda/3/2020.02/lib/python3.7/site-packages/IPython/core/history.py", line 543, in __init__
    self.new_session()
  File "</mpcdf/soft/SLE_12/packages/x86_64/anaconda/3/2020.02/lib/python3.7/site-packages/decorator.py:decorator-gen-22>", line 2, in new_session
  File "/mpcdf/soft/SLE_12/packages/x86_64/anaconda/3/2020.02/lib/python3.7/site-packages/IPython/core/history.py", line 58, in needs_sqlite
    return f(self, *a, **kw)
  File "/mpcdf/soft/SLE_12/packages/x86_64/anaconda/3/2020.02/lib/python3.7/site-packages/IPython/core/history.py", line 570, in new_session
    self.session_number = cur.lastrowid
sqlite3.OperationalError: database is locked
[TerminalIPythonApp] ERROR | Failed to create history session in /draco/u/aenge/.ipython/profile_default/history.sqlite. History will not be saved.
Traceback (most recent call last):
  File "/mpcdf/soft/SLE_12/packages/x86_64/anaconda/3/2020.02/lib/python3.7/site-packages/IPython/core/history.py", line 543, in __init__
    self.new_session()
  File "</mpcdf/soft/SLE_12/packages/x86_64/anaconda/3/2020.02/lib/python3.7/site-packages/decorator.py:decorator-gen-22>", line 2, in new_session
  File "/mpcdf/soft/SLE_12/packages/x86_64/anaconda/3/2020.02/lib/python3.7/site-packages/IPython/core/history.py", line 58, in needs_sqlite
    return f(self, *a, **kw)
  File "/mpcdf/soft/SLE_12/packages/x86_64/anaconda/3/2020.02/lib/python3.7/site-packages/IPython/core/history.py", line 569, in new_session
    NULL, "") """, (datetime.datetime.now(),))
sqlite3.OperationalError: database is locked
[TerminalIPythonApp] ERROR | Failed to create history session in /draco/u/aenge/.ipython/profile_default/history.sqlite. History will not be saved.
Traceback (most recent call last):
  File "/mpcdf/soft/SLE_12/packages/x86_64/anaconda/3/2020.02/lib/python3.7/site-packages/IPython/core/history.py", line 543, in __init__
    self.new_session()
  File "</mpcdf/soft/SLE_12/packages/x86_64/anaconda/3/2020.02/lib/python3.7/site-packages/decorator.py:decorator-gen-22>", line 2, in new_session
  File "/mpcdf/soft/SLE_12/packages/x86_64/anaconda/3/2020.02/lib/python3.7/site-packages/IPython/core/history.py", line 58, in needs_sqlite
    return f(self, *a, **kw)
  File "/mpcdf/soft/SLE_12/packages/x86_64/anaconda/3/2020.02/lib/python3.7/site-packages/IPython/core/history.py", line 569, in new_session
    NULL, "") """, (datetime.datetime.now(),))
sqlite3.OperationalError: database is locked
[TerminalIPythonApp] ERROR | Failed to create history session in /draco/u/aenge/.ipython/profile_default/history.sqlite. History will not be saved.
Traceback (most recent call last):
  File "/mpcdf/soft/SLE_12/packages/x86_64/anaconda/3/2020.02/lib/python3.7/site-packages/IPython/core/history.py", line 543, in __init__
    self.new_session()
  File "</mpcdf/soft/SLE_12/packages/x86_64/anaconda/3/2020.02/lib/python3.7/site-packages/decorator.py:decorator-gen-22>", line 2, in new_session
  File "/mpcdf/soft/SLE_12/packages/x86_64/anaconda/3/2020.02/lib/python3.7/site-packages/IPython/core/history.py", line 58, in needs_sqlite
    return f(self, *a, **kw)
  File "/mpcdf/soft/SLE_12/packages/x86_64/anaconda/3/2020.02/lib/python3.7/site-packages/IPython/core/history.py", line 569, in new_session
    NULL, "") """, (datetime.datetime.now(),))
sqlite3.OperationalError: database is locked
[TerminalIPythonApp] ERROR | Failed to open SQLite history /draco/u/aenge/.ipython/profile_default/history.sqlite (database is locked).
[TerminalIPythonApp] ERROR | History file was moved to /draco/u/aenge/.ipython/profile_default/history-corrupt-2020-12-25T15.47.17.526940.sqlite and a new file created.
[TerminalIPythonApp] ERROR | Failed to open SQLite history /draco/u/aenge/.ipython/profile_default/history.sqlite (database is locked).
[TerminalIPythonApp] ERROR | Failed to create history session in /draco/u/aenge/.ipython/profile_default/history.sqlite. History will not be saved.
Traceback (most recent call last):
  File "/mpcdf/soft/SLE_12/packages/x86_64/anaconda/3/2020.02/lib/python3.7/site-packages/IPython/core/history.py", line 543, in __init__
    self.new_session()
  File "</mpcdf/soft/SLE_12/packages/x86_64/anaconda/3/2020.02/lib/python3.7/site-packages/decorator.py:decorator-gen-22>", line 2, in new_session
  File "/mpcdf/soft/SLE_12/packages/x86_64/anaconda/3/2020.02/lib/python3.7/site-packages/IPython/core/history.py", line 58, in needs_sqlite
    return f(self, *a, **kw)
  File "/mpcdf/soft/SLE_12/packages/x86_64/anaconda/3/2020.02/lib/python3.7/site-packages/IPython/core/history.py", line 569, in new_session
    NULL, "") """, (datetime.datetime.now(),))
sqlite3.OperationalError: database is locked
[TerminalIPythonApp] ERROR | History file was moved to /draco/u/aenge/.ipython/profile_default/history-corrupt-2020-12-25T15.47.17.673963.sqlite and a new file created.
[TerminalIPythonApp] ERROR | Failed to create history session in /draco/u/aenge/.ipython/profile_default/history.sqlite. History will not be saved.
Traceback (most recent call last):
  File "/mpcdf/soft/SLE_12/packages/x86_64/anaconda/3/2020.02/lib/python3.7/site-packages/IPython/core/history.py", line 543, in __init__
    self.new_session()
  File "</mpcdf/soft/SLE_12/packages/x86_64/anaconda/3/2020.02/lib/python3.7/site-packages/decorator.py:decorator-gen-22>", line 2, in new_session
  File "/mpcdf/soft/SLE_12/packages/x86_64/anaconda/3/2020.02/lib/python3.7/site-packages/IPython/core/history.py", line 58, in needs_sqlite
    return f(self, *a, **kw)
  File "/mpcdf/soft/SLE_12/packages/x86_64/anaconda/3/2020.02/lib/python3.7/site-packages/IPython/core/history.py", line 569, in new_session
    NULL, "") """, (datetime.datetime.now(),))
sqlite3.OperationalError: database is locked
[TerminalIPythonApp] ERROR | Failed to create history session in /draco/u/aenge/.ipython/profile_default/history.sqlite. History will not be saved.
Traceback (most recent call last):
  File "/mpcdf/soft/SLE_12/packages/x86_64/anaconda/3/2020.02/lib/python3.7/site-packages/IPython/core/history.py", line 543, in __init__
    self.new_session()
  File "</mpcdf/soft/SLE_12/packages/x86_64/anaconda/3/2020.02/lib/python3.7/site-packages/decorator.py:decorator-gen-22>", line 2, in new_session
  File "/mpcdf/soft/SLE_12/packages/x86_64/anaconda/3/2020.02/lib/python3.7/site-packages/IPython/core/history.py", line 58, in needs_sqlite
    return f(self, *a, **kw)
  File "/mpcdf/soft/SLE_12/packages/x86_64/anaconda/3/2020.02/lib/python3.7/site-packages/IPython/core/history.py", line 569, in new_session
    NULL, "") """, (datetime.datetime.now(),))
sqlite3.OperationalError: database is locked
[TerminalIPythonApp] ERROR | Failed to open SQLite history /draco/u/aenge/.ipython/profile_default/history.sqlite (database is locked).
[TerminalIPythonApp] ERROR | Failed to create history session in /draco/u/aenge/.ipython/profile_default/history.sqlite. History will not be saved.
Traceback (most recent call last):
  File "/mpcdf/soft/SLE_12/packages/x86_64/anaconda/3/2020.02/lib/python3.7/site-packages/IPython/core/history.py", line 543, in __init__
    self.new_session()
  File "</mpcdf/soft/SLE_12/packages/x86_64/anaconda/3/2020.02/lib/python3.7/site-packages/decorator.py:decorator-gen-22>", line 2, in new_session
  File "/mpcdf/soft/SLE_12/packages/x86_64/anaconda/3/2020.02/lib/python3.7/site-packages/IPython/core/history.py", line 58, in needs_sqlite
    return f(self, *a, **kw)
  File "/mpcdf/soft/SLE_12/packages/x86_64/anaconda/3/2020.02/lib/python3.7/site-packages/IPython/core/history.py", line 569, in new_session
    NULL, "") """, (datetime.datetime.now(),))
sqlite3.OperationalError: database is locked
[TerminalIPythonApp] ERROR | History file was moved to /draco/u/aenge/.ipython/profile_default/history-corrupt-2020-12-25T15.47.17.864364.sqlite and a new file created.
[TerminalIPythonApp] ERROR | Failed to open SQLite history /draco/u/aenge/.ipython/profile_default/history.sqlite (database is locked).
[TerminalIPythonApp] ERROR | Failed to create history session in /draco/u/aenge/.ipython/profile_default/history.sqlite. History will not be saved.
Traceback (most recent call last):
  File "/mpcdf/soft/SLE_12/packages/x86_64/anaconda/3/2020.02/lib/python3.7/site-packages/IPython/core/history.py", line 543, in __init__
    self.new_session()
  File "</mpcdf/soft/SLE_12/packages/x86_64/anaconda/3/2020.02/lib/python3.7/site-packages/decorator.py:decorator-gen-22>", line 2, in new_session
  File "/mpcdf/soft/SLE_12/packages/x86_64/anaconda/3/2020.02/lib/python3.7/site-packages/IPython/core/history.py", line 58, in needs_sqlite
    return f(self, *a, **kw)
  File "/mpcdf/soft/SLE_12/packages/x86_64/anaconda/3/2020.02/lib/python3.7/site-packages/IPython/core/history.py", line 569, in new_session
    NULL, "") """, (datetime.datetime.now(),))
sqlite3.OperationalError: database is locked
[TerminalIPythonApp] ERROR | Failed to create history session in /draco/u/aenge/.ipython/profile_default/history.sqlite. History will not be saved.
Traceback (most recent call last):
  File "/mpcdf/soft/SLE_12/packages/x86_64/anaconda/3/2020.02/lib/python3.7/site-packages/IPython/core/history.py", line 543, in __init__
    self.new_session()
  File "</mpcdf/soft/SLE_12/packages/x86_64/anaconda/3/2020.02/lib/python3.7/site-packages/decorator.py:decorator-gen-22>", line 2, in new_session
  File "/mpcdf/soft/SLE_12/packages/x86_64/anaconda/3/2020.02/lib/python3.7/site-packages/IPython/core/history.py", line 58, in needs_sqlite
    return f(self, *a, **kw)
  File "/mpcdf/soft/SLE_12/packages/x86_64/anaconda/3/2020.02/lib/python3.7/site-packages/IPython/core/history.py", line 569, in new_session
    NULL, "") """, (datetime.datetime.now(),))
sqlite3.OperationalError: database is locked
[TerminalIPythonApp] ERROR | Failed to create history session in /draco/u/aenge/.ipython/profile_default/history.sqlite. History will not be saved.
Traceback (most recent call last):
  File "/mpcdf/soft/SLE_12/packages/x86_64/anaconda/3/2020.02/lib/python3.7/site-packages/IPython/core/history.py", line 543, in __init__
    self.new_session()
  File "</mpcdf/soft/SLE_12/packages/x86_64/anaconda/3/2020.02/lib/python3.7/site-packages/decorator.py:decorator-gen-22>", line 2, in new_session
  File "/mpcdf/soft/SLE_12/packages/x86_64/anaconda/3/2020.02/lib/python3.7/site-packages/IPython/core/history.py", line 58, in needs_sqlite
    return f(self, *a, **kw)
  File "/mpcdf/soft/SLE_12/packages/x86_64/anaconda/3/2020.02/lib/python3.7/site-packages/IPython/core/history.py", line 569, in new_session
    NULL, "") """, (datetime.datetime.now(),))
sqlite3.OperationalError: database is locked
[TerminalIPythonApp] ERROR | Failed to open SQLite history /draco/u/aenge/.ipython/profile_default/history.sqlite (database is locked).
[TerminalIPythonApp] ERROR | Failed to open SQLite history /draco/u/aenge/.ipython/profile_default/history.sqlite (database is locked).
[TerminalIPythonApp] ERROR | Failed to open SQLite history /draco/u/aenge/.ipython/profile_default/history.sqlite (database is locked).
[TerminalIPythonApp] ERROR | History file was moved to /draco/u/aenge/.ipython/profile_default/history-corrupt.sqlite and a new file created.
[TerminalIPythonApp] ERROR | Failed to open SQLite history /draco/u/aenge/.ipython/profile_default/history.sqlite (disk I/O error).
[TerminalIPythonApp] ERROR | History file was moved to /draco/u/aenge/.ipython/profile_default/history-corrupt.sqlite and a new file created.
Traceback (most recent call last):
  File "/mpcdf/soft/SLE_12/packages/x86_64/anaconda/3/2020.02/lib/python3.7/site-packages/IPython/core/history.py", line 87, in catch_corrupt_db
    return f(self, *a, **kw)
  File "/mpcdf/soft/SLE_12/packages/x86_64/anaconda/3/2020.02/lib/python3.7/site-packages/IPython/core/history.py", line 257, in init_db
    end timestamp, num_cmds integer, remark text)""")
sqlite3.OperationalError: database is locked

During handling of the above exception, another exception occurred:

Traceback (most recent call last):
  File "/mpcdf/soft/SLE_12/packages/x86_64/anaconda/3/2020.02/bin/ipython", line 11, in <module>
    sys.exit(start_ipython())
  File "/mpcdf/soft/SLE_12/packages/x86_64/anaconda/3/2020.02/lib/python3.7/site-packages/IPython/__init__.py", line 126, in start_ipython
    return launch_new_instance(argv=argv, **kwargs)
  File "/mpcdf/soft/SLE_12/packages/x86_64/anaconda/3/2020.02/lib/python3.7/site-packages/traitlets/config/application.py", line 663, in launch_instance
    app.initialize(argv)
  File "</mpcdf/soft/SLE_12/packages/x86_64/anaconda/3/2020.02/lib/python3.7/site-packages/decorator.py:decorator-gen-113>", line 2, in initialize
  File "/mpcdf/soft/SLE_12/packages/x86_64/anaconda/3/2020.02/lib/python3.7/site-packages/traitlets/config/application.py", line 87, in catch_config_error
    return method(app, *args, **kwargs)
  File "/mpcdf/soft/SLE_12/packages/x86_64/anaconda/3/2020.02/lib/python3.7/site-packages/IPython/terminal/ipapp.py", line 317, in initialize
    self.init_shell()
  File "/mpcdf/soft/SLE_12/packages/x86_64/anaconda/3/2020.02/lib/python3.7/site-packages/IPython/terminal/ipapp.py", line 333, in init_shell
    ipython_dir=self.ipython_dir, user_ns=self.user_ns)
  File "/mpcdf/soft/SLE_12/packages/x86_64/anaconda/3/2020.02/lib/python3.7/site-packages/traitlets/config/configurable.py", line 412, in instance
    inst = cls(*args, **kwargs)
Traceback (most recent call last):
  File "/mpcdf/soft/SLE_12/packages/x86_64/anaconda/3/2020.02/lib/python3.7/site-packages/IPython/core/history.py", line 87, in catch_corrupt_db
    return f(self, *a, **kw)
  File "/mpcdf/soft/SLE_12/packages/x86_64/anaconda/3/2020.02/lib/python3.7/site-packages/IPython/core/history.py", line 257, in init_db
    end timestamp, num_cmds integer, remark text)""")
sqlite3.OperationalError: database is locked

During handling of the above exception, another exception occurred:

Traceback (most recent call last):
  File "/mpcdf/soft/SLE_12/packages/x86_64/anaconda/3/2020.02/bin/ipython", line 11, in <module>
    sys.exit(start_ipython())
  File "/mpcdf/soft/SLE_12/packages/x86_64/anaconda/3/2020.02/lib/python3.7/site-packages/IPython/__init__.py", line 126, in start_ipython
    return launch_new_instance(argv=argv, **kwargs)
  File "/mpcdf/soft/SLE_12/packages/x86_64/anaconda/3/2020.02/lib/python3.7/site-packages/traitlets/config/application.py", line 663, in launch_instance
  File "/mpcdf/soft/SLE_12/packages/x86_64/anaconda/3/2020.02/lib/python3.7/site-packages/IPython/terminal/interactiveshell.py", line 519, in __init__
    super(TerminalInteractiveShell, self).__init__(*args, **kwargs)
  File "/mpcdf/soft/SLE_12/packages/x86_64/anaconda/3/2020.02/lib/python3.7/site-packages/IPython/core/interactiveshell.py", line 661, in __init__
    self.init_history()
  File "/mpcdf/soft/SLE_12/packages/x86_64/anaconda/3/2020.02/lib/python3.7/site-packages/IPython/core/interactiveshell.py", line 1802, in init_history
    self.history_manager = HistoryManager(shell=self, parent=self)
  File "/mpcdf/soft/SLE_12/packages/x86_64/anaconda/3/2020.02/lib/python3.7/site-packages/IPython/core/history.py", line 537, in __init__
    **traits)
  File "/mpcdf/soft/SLE_12/packages/x86_64/anaconda/3/2020.02/lib/python3.7/site-packages/IPython/core/history.py", line 229, in __init__
    self.init_db()
    app.initialize(argv)
  File "</mpcdf/soft/SLE_12/packages/x86_64/anaconda/3/2020.02/lib/python3.7/site-packages/decorator.py:decorator-gen-113>", line 2, in initialize
  File "/mpcdf/soft/SLE_12/packages/x86_64/anaconda/3/2020.02/lib/python3.7/site-packages/traitlets/config/application.py", line 87, in catch_config_error
    return method(app, *args, **kwargs)
  File "/mpcdf/soft/SLE_12/packages/x86_64/anaconda/3/2020.02/lib/python3.7/site-packages/IPython/terminal/ipapp.py", line 317, in initialize
    self.init_shell()
  File "/mpcdf/soft/SLE_12/packages/x86_64/anaconda/3/2020.02/lib/python3.7/site-packages/IPython/terminal/ipapp.py", line 333, in init_shell
    ipython_dir=self.ipython_dir, user_ns=self.user_ns)
  File "/mpcdf/soft/SLE_12/packages/x86_64/anaconda/3/2020.02/lib/python3.7/site-packages/traitlets/config/configurable.py", line 412, in instance
    inst = cls(*args, **kwargs)
  File "</mpcdf/soft/SLE_12/packages/x86_64/anaconda/3/2020.02/lib/python3.7/site-packages/decorator.py:decorator-gen-15>", line 2, in init_db
  File "/mpcdf/soft/SLE_12/packages/x86_64/anaconda/3/2020.02/lib/python3.7/site-packages/IPython/core/history.py", line 98, in catch_corrupt_db
    size = os.stat(self.hist_file).st_size
FileNotFoundError: [Errno 2] No such file or directory: '/draco/u/aenge/.ipython/profile_default/history.sqlite'

If you suspect this is an IPython 7.12.0 bug, please report it at:
    https://github.com/ipython/ipython/issues
or send an email to the mailing list at ipython-dev@python.org

You can print a more detailed traceback right now with "%tb", or use "%debug"
to interactively debug it.

Extra-detailed tracebacks for bug-reporting purposes can be enabled via:
    c.Application.verbose_crash=True

  File "/mpcdf/soft/SLE_12/packages/x86_64/anaconda/3/2020.02/lib/python3.7/site-packages/IPython/terminal/interactiveshell.py", line 519, in __init__
    super(TerminalInteractiveShell, self).__init__(*args, **kwargs)
  File "/mpcdf/soft/SLE_12/packages/x86_64/anaconda/3/2020.02/lib/python3.7/site-packages/IPython/core/interactiveshell.py", line 661, in __init__
    self.init_history()
  File "/mpcdf/soft/SLE_12/packages/x86_64/anaconda/3/2020.02/lib/python3.7/site-packages/IPython/core/interactiveshell.py", line 1802, in init_history
    self.history_manager = HistoryManager(shell=self, parent=self)
  File "/mpcdf/soft/SLE_12/packages/x86_64/anaconda/3/2020.02/lib/python3.7/site-packages/IPython/core/history.py", line 537, in __init__
    **traits)
  File "/mpcdf/soft/SLE_12/packages/x86_64/anaconda/3/2020.02/lib/python3.7/site-packages/IPython/core/history.py", line 229, in __init__
    self.init_db()
Traceback (most recent call last):
  File "/mpcdf/soft/SLE_12/packages/x86_64/anaconda/3/2020.02/lib/python3.7/site-packages/IPython/core/history.py", line 87, in catch_corrupt_db
    return f(self, *a, **kw)
  File "/mpcdf/soft/SLE_12/packages/x86_64/anaconda/3/2020.02/lib/python3.7/site-packages/IPython/core/history.py", line 257, in init_db
    end timestamp, num_cmds integer, remark text)""")
sqlite3.OperationalError: database is locked

During handling of the above exception, another exception occurred:

Traceback (most recent call last):
  File "/mpcdf/soft/SLE_12/packages/x86_64/anaconda/3/2020.02/bin/ipython", line 11, in <module>
    sys.exit(start_ipython())
  File "/mpcdf/soft/SLE_12/packages/x86_64/anaconda/3/2020.02/lib/python3.7/site-packages/IPython/__init__.py", line 126, in start_ipython
    return launch_new_instance(argv=argv, **kwargs)
  File "/mpcdf/soft/SLE_12/packages/x86_64/anaconda/3/2020.02/lib/python3.7/site-packages/traitlets/config/application.py", line 663, in launch_instance
  File "</mpcdf/soft/SLE_12/packages/x86_64/anaconda/3/2020.02/lib/python3.7/site-packages/decorator.py:decorator-gen-15>", line 2, in init_db
  File "/mpcdf/soft/SLE_12/packages/x86_64/anaconda/3/2020.02/lib/python3.7/site-packages/IPython/core/history.py", line 113, in catch_corrupt_db
    os.rename(self.hist_file, newpath)
FileNotFoundError: [Errno 2] No such file or directory: '/draco/u/aenge/.ipython/profile_default/history.sqlite' -> '/draco/u/aenge/.ipython/profile_default/history-corrupt.sqlite'

If you suspect this is an IPython 7.12.0 bug, please report it at:
    https://github.com/ipython/ipython/issues
or send an email to the mailing list at ipython-dev@python.org

You can print a more detailed traceback right now with "%tb", or use "%debug"
to interactively debug it.

Extra-detailed tracebacks for bug-reporting purposes can be enabled via:
    c.Application.verbose_crash=True

    app.initialize(argv)
  File "</mpcdf/soft/SLE_12/packages/x86_64/anaconda/3/2020.02/lib/python3.7/site-packages/decorator.py:decorator-gen-113>", line 2, in initialize
  File "/mpcdf/soft/SLE_12/packages/x86_64/anaconda/3/2020.02/lib/python3.7/site-packages/traitlets/config/application.py", line 87, in catch_config_error
    return method(app, *args, **kwargs)
  File "/mpcdf/soft/SLE_12/packages/x86_64/anaconda/3/2020.02/lib/python3.7/site-packages/IPython/terminal/ipapp.py", line 317, in initialize
    self.init_shell()
  File "/mpcdf/soft/SLE_12/packages/x86_64/anaconda/3/2020.02/lib/python3.7/site-packages/IPython/terminal/ipapp.py", line 333, in init_shell
    ipython_dir=self.ipython_dir, user_ns=self.user_ns)
  File "/mpcdf/soft/SLE_12/packages/x86_64/anaconda/3/2020.02/lib/python3.7/site-packages/traitlets/config/configurable.py", line 412, in instance
    inst = cls(*args, **kwargs)
  File "/mpcdf/soft/SLE_12/packages/x86_64/anaconda/3/2020.02/lib/python3.7/site-packages/IPython/terminal/interactiveshell.py", line 519, in __init__
    super(TerminalInteractiveShell, self).__init__(*args, **kwargs)
  File "/mpcdf/soft/SLE_12/packages/x86_64/anaconda/3/2020.02/lib/python3.7/site-packages/IPython/core/interactiveshell.py", line 661, in __init__
    self.init_history()
  File "/mpcdf/soft/SLE_12/packages/x86_64/anaconda/3/2020.02/lib/python3.7/site-packages/IPython/core/interactiveshell.py", line 1802, in init_history
    self.history_manager = HistoryManager(shell=self, parent=self)
  File "/mpcdf/soft/SLE_12/packages/x86_64/anaconda/3/2020.02/lib/python3.7/site-packages/IPython/core/history.py", line 537, in __init__
    **traits)
  File "/mpcdf/soft/SLE_12/packages/x86_64/anaconda/3/2020.02/lib/python3.7/site-packages/IPython/core/history.py", line 229, in __init__
    self.init_db()
  File "</mpcdf/soft/SLE_12/packages/x86_64/anaconda/3/2020.02/lib/python3.7/site-packages/decorator.py:decorator-gen-15>", line 2, in init_db
  File "/mpcdf/soft/SLE_12/packages/x86_64/anaconda/3/2020.02/lib/python3.7/site-packages/IPython/core/history.py", line 98, in catch_corrupt_db
    size = os.stat(self.hist_file).st_size
FileNotFoundError: [Errno 2] No such file or directory: '/draco/u/aenge/.ipython/profile_default/history.sqlite'

If you suspect this is an IPython 7.12.0 bug, please report it at:
    https://github.com/ipython/ipython/issues
or send an email to the mailing list at ipython-dev@python.org

You can print a more detailed traceback right now with "%tb", or use "%debug"
to interactively debug it.

Extra-detailed tracebacks for bug-reporting purposes can be enabled via:
    c.Application.verbose_crash=True

[TerminalIPythonApp] ERROR | Failed to open SQLite history /draco/u/aenge/.ipython/profile_default/history.sqlite (disk I/O error).
[TerminalIPythonApp] ERROR | Failed to load history too many times, history will not be saved.
[TerminalIPythonApp] ERROR | Failed to create history session in /draco/u/aenge/.ipython/profile_default/history.sqlite. History will not be saved.
Traceback (most recent call last):
  File "/mpcdf/soft/SLE_12/packages/x86_64/anaconda/3/2020.02/lib/python3.7/site-packages/IPython/core/history.py", line 543, in __init__
    self.new_session()
  File "</mpcdf/soft/SLE_12/packages/x86_64/anaconda/3/2020.02/lib/python3.7/site-packages/decorator.py:decorator-gen-22>", line 2, in new_session
  File "/mpcdf/soft/SLE_12/packages/x86_64/anaconda/3/2020.02/lib/python3.7/site-packages/IPython/core/history.py", line 58, in needs_sqlite
    return f(self, *a, **kw)
  File "/mpcdf/soft/SLE_12/packages/x86_64/anaconda/3/2020.02/lib/python3.7/site-packages/IPython/core/history.py", line 569, in new_session
    NULL, "") """, (datetime.datetime.now(),))
sqlite3.OperationalError: database is locked
[TerminalIPythonApp] ERROR | Failed to create history session in /draco/u/aenge/.ipython/profile_default/history.sqlite. History will not be saved.
Traceback (most recent call last):
  File "/mpcdf/soft/SLE_12/packages/x86_64/anaconda/3/2020.02/lib/python3.7/site-packages/IPython/core/history.py", line 543, in __init__
    self.new_session()
  File "</mpcdf/soft/SLE_12/packages/x86_64/anaconda/3/2020.02/lib/python3.7/site-packages/decorator.py:decorator-gen-22>", line 2, in new_session
  File "/mpcdf/soft/SLE_12/packages/x86_64/anaconda/3/2020.02/lib/python3.7/site-packages/IPython/core/history.py", line 58, in needs_sqlite
    return f(self, *a, **kw)
  File "/mpcdf/soft/SLE_12/packages/x86_64/anaconda/3/2020.02/lib/python3.7/site-packages/IPython/core/history.py", line 569, in new_session
    NULL, "") """, (datetime.datetime.now(),))
sqlite3.OperationalError: attempt to write a readonly database
[TerminalIPythonApp] ERROR | Failed to open SQLite history /draco/u/aenge/.ipython/profile_default/history.sqlite (database is locked).
[TerminalIPythonApp] ERROR | History file was moved to /draco/u/aenge/.ipython/profile_default/history-corrupt.sqlite and a new file created.
[TerminalIPythonApp] ERROR | Failed to open SQLite history /draco/u/aenge/.ipython/profile_default/history.sqlite (database is locked).
Traceback (most recent call last):
  File "/mpcdf/soft/SLE_12/packages/x86_64/anaconda/3/2020.02/lib/python3.7/site-packages/IPython/core/history.py", line 87, in catch_corrupt_db
    return f(self, *a, **kw)
  File "/mpcdf/soft/SLE_12/packages/x86_64/anaconda/3/2020.02/lib/python3.7/site-packages/IPython/core/history.py", line 257, in init_db
    end timestamp, num_cmds integer, remark text)""")
sqlite3.OperationalError: database is locked

During handling of the above exception, another exception occurred:

Traceback (most recent call last):
  File "/mpcdf/soft/SLE_12/packages/x86_64/anaconda/3/2020.02/bin/ipython", line 11, in <module>
    sys.exit(start_ipython())
  File "/mpcdf/soft/SLE_12/packages/x86_64/anaconda/3/2020.02/lib/python3.7/site-packages/IPython/__init__.py", line 126, in start_ipython
    return launch_new_instance(argv=argv, **kwargs)
  File "/mpcdf/soft/SLE_12/packages/x86_64/anaconda/3/2020.02/lib/python3.7/site-packages/traitlets/config/application.py", line 663, in launch_instance
    app.initialize(argv)
  File "</mpcdf/soft/SLE_12/packages/x86_64/anaconda/3/2020.02/lib/python3.7/site-packages/decorator.py:decorator-gen-113>", line 2, in initialize
  File "/mpcdf/soft/SLE_12/packages/x86_64/anaconda/3/2020.02/lib/python3.7/site-packages/traitlets/config/application.py", line 87, in catch_config_error
    return method(app, *args, **kwargs)
  File "/mpcdf/soft/SLE_12/packages/x86_64/anaconda/3/2020.02/lib/python3.7/site-packages/IPython/terminal/ipapp.py", line 317, in initialize
    self.init_shell()
  File "/mpcdf/soft/SLE_12/packages/x86_64/anaconda/3/2020.02/lib/python3.7/site-packages/IPython/terminal/ipapp.py", line 333, in init_shell
    ipython_dir=self.ipython_dir, user_ns=self.user_ns)
  File "/mpcdf/soft/SLE_12/packages/x86_64/anaconda/3/2020.02/lib/python3.7/site-packages/traitlets/config/configurable.py", line 412, in instance
    inst = cls(*args, **kwargs)
  File "/mpcdf/soft/SLE_12/packages/x86_64/anaconda/3/2020.02/lib/python3.7/site-packages/IPython/terminal/interactiveshell.py", line 519, in __init__
    super(TerminalInteractiveShell, self).__init__(*args, **kwargs)
  File "/mpcdf/soft/SLE_12/packages/x86_64/anaconda/3/2020.02/lib/python3.7/site-packages/IPython/core/interactiveshell.py", line 661, in __init__
    self.init_history()
  File "/mpcdf/soft/SLE_12/packages/x86_64/anaconda/3/2020.02/lib/python3.7/site-packages/IPython/core/interactiveshell.py", line 1802, in init_history
    self.history_manager = HistoryManager(shell=self, parent=self)
  File "/mpcdf/soft/SLE_12/packages/x86_64/anaconda/3/2020.02/lib/python3.7/site-packages/IPython/core/history.py", line 537, in __init__
    **traits)
  File "/mpcdf/soft/SLE_12/packages/x86_64/anaconda/3/2020.02/lib/python3.7/site-packages/IPython/core/history.py", line 229, in __init__
    self.init_db()
  File "</mpcdf/soft/SLE_12/packages/x86_64/anaconda/3/2020.02/lib/python3.7/site-packages/decorator.py:decorator-gen-15>", line 2, in init_db
  File "/mpcdf/soft/SLE_12/packages/x86_64/anaconda/3/2020.02/lib/python3.7/site-packages/IPython/core/history.py", line 98, in catch_corrupt_db
    size = os.stat(self.hist_file).st_size
FileNotFoundError: [Errno 2] No such file or directory: '/draco/u/aenge/.ipython/profile_default/history.sqlite'

If you suspect this is an IPython 7.12.0 bug, please report it at:
    https://github.com/ipython/ipython/issues
or send an email to the mailing list at ipython-dev@python.org

You can print a more detailed traceback right now with "%tb", or use "%debug"
to interactively debug it.

Extra-detailed tracebacks for bug-reporting purposes can be enabled via:
    c.Application.verbose_crash=True

[TerminalIPythonApp] ERROR | Failed to open SQLite history /draco/u/aenge/.ipython/profile_default/history.sqlite (database is locked).
[TerminalIPythonApp] ERROR | Failed to create history session in /draco/u/aenge/.ipython/profile_default/history.sqlite. History will not be saved.
Traceback (most recent call last):
  File "/mpcdf/soft/SLE_12/packages/x86_64/anaconda/3/2020.02/lib/python3.7/site-packages/IPython/core/history.py", line 543, in __init__
    self.new_session()
  File "</mpcdf/soft/SLE_12/packages/x86_64/anaconda/3/2020.02/lib/python3.7/site-packages/decorator.py:decorator-gen-22>", line 2, in new_session
  File "/mpcdf/soft/SLE_12/packages/x86_64/anaconda/3/2020.02/lib/python3.7/site-packages/IPython/core/history.py", line 58, in needs_sqlite
    return f(self, *a, **kw)
  File "/mpcdf/soft/SLE_12/packages/x86_64/anaconda/3/2020.02/lib/python3.7/site-packages/IPython/core/history.py", line 569, in new_session
    NULL, "") """, (datetime.datetime.now(),))
sqlite3.OperationalError: database is locked
[TerminalIPythonApp] ERROR | History file was moved to /draco/u/aenge/.ipython/profile_default/history-corrupt-2020-12-25T15.47.18.292365.sqlite and a new file created.
srun: error: dra0186: task 814: Exited with exit code 1
srun: Terminating job step 18264105.0
srun: error: dra0187: task 833: Exited with exit code 1
srun: error: dra0173: task 387: Exited with exit code 1
slurmstepd: error: *** STEP 18264105.0 ON dra0161 CANCELLED AT 2020-12-25T15:47:18 ***
srun: error: dra0190: tasks 928-959: Terminated
srun: error: dra0187: tasks 832,834-863: Terminated
srun: error: dra0191: tasks 960-991: Terminated
srun: error: dra0168: tasks 224-255: Terminated
srun: error: dra0189: tasks 896-927: Terminated
srun: error: dra0176: tasks 480-511: Terminated
srun: error: dra0175: tasks 448-450,452-479: Terminated
srun: error: dra0179: tasks 576-607: Terminated
srun: error: dra0181: tasks 640-671: Terminated
srun: error: dra0175: task 451: Exited with exit code 1
srun: error: dra0192: tasks 992-1023: Terminated
srun: error: dra0173: tasks 384-386,388-415: Terminated
srun: error: dra0165: tasks 128-159: Terminated
srun: error: dra0182: tasks 672-703: Terminated
srun: error: dra0186: tasks 800-813,815-831: Terminated
srun: error: dra0178: tasks 544-575: Terminated
srun: error: dra0188: tasks 864-895: Terminated
srun: error: dra0170: tasks 288-319: Terminated
srun: error: dra0161: tasks 0-31: Terminated
srun: error: dra0184: tasks 736-767: Terminated
srun: error: dra0185: tasks 768-799: Terminated
srun: error: dra0164: tasks 96-127: Terminated
srun: error: dra0177: tasks 512-543: Terminated
srun: error: dra0163: tasks 64-95: Terminated
srun: error: dra0172: tasks 352-383: Terminated
srun: error: dra0166: tasks 160-191: Terminated
srun: error: dra0183: tasks 704-735: Terminated
srun: error: dra0162: tasks 32-63: Terminated
srun: error: dra0171: tasks 320-351: Terminated
srun: error: dra0169: tasks 256-287: Terminated
srun: error: dra0167: tasks 192-223: Terminated
srun: error: dra0180: tasks 608-639: Terminated
srun: error: dra0174: tasks 416-447: Terminated
srun: Force Terminated job step 18264105.0
